Workbook

Sheet Tableau de Bord
B2: 2A-COMMERCE QUINCAILLERIE - TABLEAU DE BORD
B3: Indicateurs clés de performance & suivi global du stock
B5: CHIFFRE D'AFFAIRES TOTAL | D5: MARGE BRUTE TOTALE | F5: VALEUR DU STOCK ACTUEL | H5: ARTICLES EN ALERTE
B6: =SUM(Mouvements!G5:G990) -> 2639800 | D6: {=SUMPRODUCT((Mouvements!B5:B990="Sortie")*(Mouvements!E5:E990)*(Mouvements!F5:F990-_xludf.XLOOKUP(Mouvements!C5:C990,Catalogue!A5:A1379,Catalogue!F5:F1375,0)))} -> #NAME? | F6: {=SUMPRODUCT(Catalogue!N5:N1375*Catalogue!F5:F1375)} -> 4145012 | H6: =COUNTIF(Catalogue!P5:P1375, "RÉAPPROVISIONNER") -> 350
B9: RÉCAPITULATIF PAR CATÉGORIE
B10: Catégorie | C10: Nb Articles | D10: Valeur Stock (Achat) | E10: Ventes Cumulées (FCFA)
B11: Gros œuvre | C11: =COUNTIF(Catalogue!C$5:C$231, B11) -> 10 | D11: {=SUMPRODUCT((Catalogue!C$5:C$231=B11)*(Catalogue!N$5:N$231)*(Catalogue!F$5:F$231))} -> 477654 | E11: =SUMIFS(Mouvements!G$5:G$990, Mouvements!D$5:D$990, B11, Mouvements!B$5:B$990, "Sortie") -> 0
B12: Ferraille | C12: =COUNTIF(Catalogue!C$5:C$231, B12) -> 11 | D12: {=SUMPRODUCT((Catalogue!C$5:C$231=B12)*(Catalogue!N$5:N$231)*(Catalogue!F$5:F$231))} -> 37250 | E12: =SUMIFS(Mouvements!G$5:G$990, Mouvements!D$5:D$990, B12, Mouvements!B$5:B$990, "Sortie") -> 0
B13: Plomberie | C13: =COUNTIF(Catalogue!C$5:C$231, B13) -> 78 | D13: {=SUMPRODUCT((Catalogue!C$5:C$231=B13)*(Catalogue!N$5:N$231)*(Catalogue!F$5:F$231))} -> 602050 | E13: =SUMIFS(Mouvements!G$5:G$990, Mouvements!D$5:D$990, B13, Mouvements!B$5:B$990, "Sortie") -> 0
B14: Électricité | C14: =COUNTIF(Catalogue!C$5:C$231, B14) -> 29 | D14: {=SUMPRODUCT((Catalogue!C$5:C$231=B14)*(Catalogue!N$5:N$231)*(Catalogue!F$5:F$231))} -> 804500 | E14: =SUMIFS(Mouvements!G$5:G$990, Mouvements!D$5:D$990, B14, Mouvements!B$5:B$990, "Sortie") -> 0
B15: Outillage / Peinture | C15: =COUNTIF(Catalogue!C$5:C$231, B15) -> 99 | D15: {=SUMPRODUCT((Catalogue!C$5:C$231=B15)*(Catalogue!N$5:N$231)*(Catalogue!F$5:F$231))} -> 902358 | E15: =SUMIFS(Mouvements!G$5:G$990, Mouvements!D$5:D$990, B15, Mouvements!B$5:B$990, "Sortie") -> 0
B16: TOTAL | C16: =SUM(C11:C15) -> 227 | D16: =SUM(D11:D15) -> 2823812 | E16: =SUM(E11:E15) -> 0

Sheet Catalogue
A2: CATALOGUE & ÉTAT DU STOCK
A3: Liste des articles, tarification et suivi automatisé des stocks
A4: Marque | B4: Désignation | C4: Catégorie | D4: Unité | E4: Prix au Mètre/Kg | F4: Prix Achat (FCFA) | G4: Prix Vente (FCFA) | H4: Marge (%) | I4: Stock Initial | J4: Seuil mini de vente | K4: Seuil mini de vente au metre/Kg | L4: Entrées | M4: Sorties | N4: Stock Actuel | O4: Seuil Alerte | P4: Statut Stock | Q4: Valeur Stock (FCFA)
A5: CIM IVOIRE | B5: Ciment CPJ 42.5 (Sachet 50kg) | C5: Gros œuvre | D5: Sac | F5: 4500 | G5: 5000 | H5: 0.11111111 | I5: 15 | J5: 5000 | L5: 0 | M5: 0 | N5: 15 | O5: 20 | P5: RÉAPPROVISIONNER | Q5: 67500
A6: SOTICI | B6: Fer à béton Ø 10 (Barre 12m) | C6: Ferraille | D6: Barre | F6: 0 | G6: 0 | I6: 0 | L6: 0 | M6: 0 | N6: 0 | O6: 50 | P6: RÉAPPROVISIONNER | Q6: 0
B7: TUYAUX PRESSION 16/20 6M PN 10 | C7: Plomberie | D7: Barre | E7: 600 | F7: 1500 | G7: 3000 | H7: 1 | I7: 40 | J7: 2500 | L7: 0 | M7: 0 | N7: 40 | O7: 10 | P7: OK | Q7: 60000
A8: DELUX INDUSTRAP | B8: Delux Peinture Vinilique Mat 30Kg EXT | C8: Outillage / Peinture | D8: Seau | F8: 23500 | G8: 25000 | H8: 0.063829787 | I8: 6 | J8: 24000 | L8: 0 | M8: 0 | N8: 6 | O8: 5 | P8: OK | Q8: 141000
A9: DELUX INDUSTRAP | B9: Delux Peinture Vinilique Mat 30Kg INT | C9: Outillage / Peinture | D9: Seau | F9: 21500 | G9: 23000 | H9: 0.069767442 | I9: 4 | J9: 22000 | L9: 0 | M9: 0 | N9: 4 | P9: OK | Q9: 86000
A10: PLASTICABLE | B10: Câble Électrique TH 2X1.5 (Rouleau 100m) | C10: Électricité | D10: Rouleau | E10: 600 | F10: 47500 | G10: 50000 | H10: 0.052631579 | I10: 1 | K10: 500 | L10: 0 | M10: 0 | N10: 1 | O10: 8 | P10: RÉAPPROVISIONNER | Q10: 47500
A11: B METERS | B11: SOUS COMPTEUR D'EAU EN FER GM | C11: Plomberie | D11: Unité | F11: 4000 | G11: 6000 | H11: 0.5 | I11: 1 | J11: 5000 | L11: 0 | M11: 0 | N11: 1 | P11: OK
A12: FORCE | B12: SOUS COMPTEUR D'EAU EN FER GM | C12: Plomberie | D12: Unité | F12: 4000 | G12: 6000 | H12: 0.5 | I12: 2 | J12: 5000 | L12: 0 | M12: 0 | N12: 2 | O12: 8 | P12: RÉAPPROVISIONNER | Q12: 8000
A13: INDUSTRAP | B13: Milano Peinture Vinilique 5Kg INT/EXT | C13: Outillage / Peinture | D13: Seau | F13: 2300 | G13: 3500 | H13: 0.52173913 | I13: 4 | J13: 3000 | L13: 0 | M13: 0 | N13: 4 | O13: 8 | P13: RÉAPPROVISIONNER | Q13: 9200
A14: INDUSTRAP | B14: Milano Peinture Vinilique 15Kg INT/EXT | C14: Outillage / Peinture | D14: Seau | F14: 7500 | G14: 8500 | H14: 0.13333333 | I14: 3 | J14: 8000 | L14: 0 | M14: 0 | N14: 3 | O14: 8 | P14: RÉAPPROVISIONNER | Q14: 22500
A15: INDUSTRAP | B15: Milano Peinture Vinilique 30Kg INT/EXT | C15: Outillage / Peinture | D15: Seau | F15: 14300 | G15: 16000 | H15: 0.11888112 | I15: 4 | J15: 15000 | L15: 0 | M15: 0 | N15: 4 | O15: 8 | P15: RÉAPPROVISIONNER | Q15: 57200
A16: INDUSTRAP | B16: TRAPEAU INT 5Kg | C16: Outillage / Peinture | D16: Seau | F16: 2200 | G16: 3000 | H16: 0.36363636 | I16: 6 | J16: 2700 | L16: 0 | M16: 0 | N16: 6 | O16: 8 | P16: RÉAPPROVISIONNER | Q16: 13200
A17: INDUSTRAP | B17: TRAPEAU INT 15Kg | C17: Outillage / Peinture | D17: Seau | F17: 6500 | G17: 8000 | H17: 0.23076923 | I17: 4 | J17: 8000 | L17: 0 | M17: 0 | N17: 4 | O17: 8 | P17: RÉAPPROVISIONNER | Q17: 26000
A18: INDUSTRAP | B18: TRAPEAU INT 30Kg | C18: Outillage / Peinture | D18: Seau | F18: 12500 | G18: 14000 | H18: 0.12 | I18: 3 | J18: 13500 | L18: 0 | M18: 0 | N18: 3 | O18: 8 | P18: RÉAPPROVISIONNER | Q18: 37500
A19: SNPC | B19: SUPER PLUS INT/EXT 5Kg | C19: Outillage / Peinture | D19: Seau | F19: 2300 | G19: 3500 | H19: 0.52173913 | J19: 3000 | L19: 0 | M19: 0 | N19: 0 | O19: 8 | P19: RÉAPPROVISIONNER | Q19: 0
A20: SNPC | B20: SUPER PLUS INT/EXT 15Kg | C20: Outillage / Peinture | D20: Seau | F20: 6300 | G20: 8000 | H20: 0.26984127 | L20: 0 | M20: 0 | N20: 0 | O20: 8 | P20: RÉAPPROVISIONNER | Q20: 0
A21: SIPPEC | B21: COUDE PVC 110 EVAC | C21: Plomberie | D21: Tuyaux | F21: 650 | G21: 1000 | H21: 0.53846154 | J21: 800 | L21: 0 | M21: 0 | N21: 0 | O21: 8 | P21: RÉAPPROVISIONNER | Q21: 0
A22: SETR | B22: BUTUME 20Kg | C22: Gros œuvre | D22: Sac | F22: 11500 | G22: 15000 | H22: 0.30434783 | I22: 2 | J22: 13000 | L22: 0 | M22: 0 | N22: 2 | O22: 8 | P22: RÉAPPROVISIONNER | Q22: 23000
A23: MEGALEC | B23: COFFRET 2 MODULES APPARENT 2702 | C23: Électricité | D23: Unité | F23: 300 | G23: 1000 | H23: 2.3333333 | I23: 5 | J23: 600 | L23: 0 | M23: 0 | N23: 5 | O23: 8 | P23: RÉAPPROVISIONNER | Q23: 1500
A24: FORCE | B24: Flexible de Mitigeur 60CM WK-JN04 | C24: Plomberie | D24: Unité | F24: 700 | G24: 1000 | H24: 0.42857143 | I24: 10 | J24: 1000 | L24: 0 | M24: 0 | N24: 10 | O24: 8 | P24: OK | Q24: 7000
A25: CHEVAL | B25: Colorant Jaune Oxyde | C25: Outillage / Peinture | D25: Unité | F25: 750 | G25: 1000 | H25: 0.33333333 | I25: 20 | J25: 1000 | L25: 0 | M25: 0 | N25: 19 | O25: 8 | P25: OK | Q25: 15000
A26: CHEVAL | B26: Colorant Jaune Vert | C26: Outillage / Peinture | D26: Unité | F26: 750 | G26: 1000 | H26: 0.33333333 | I26: 9 | L26: 0 | M26: 0 | N26: 8 | O26: 8 | P26: RÉAPPROVISIONNER | Q26: 6750
A27: CHEVAL | B27: Colorant Jaune Violet | C27: Outillage / Peinture | D27: Unité | F27: 750 | G27: 1000 | H27: 0.33333333 | L27: 0 | M27: 0 | N27: 0 | O27: 8 | P27: RÉAPPROVISIONNER | Q27: 0
A28: CHEVAL | B28: Colorant Jaune Orange | C28: Outillage / Peinture | D28: Unité | F28: 750 | G28: 1000 | H28: 0.33333333 | L28: 0 | M28: 0 | N28: 0 | O28: 8 | P28: RÉAPPROVISIONNER | Q28: 0
A29: CHEVAL | B29: Colorant Jaune Orange | C29: Outillage / Peinture | D29: Unité | F29: 750 | G29: 1000 | H29: 0.33333333 | L29: 0 | M29: 0 | N29: 0 | O29: 8 | P29: RÉAPPROVISIONNER | Q29: 0
A30: CHEVAL | B30: Colorant Jaune Rouge | C30: Outillage / Peinture | D30: Unité | F30: 750 | G30: 1000 | H30: 0.33333333 | L30: 0 | M30: 0 | N30: 0 | O30: 8 | P30: RÉAPPROVISIONNER | Q30: 0
A31: INDUSTRAP | B31: Colorant noir | C31: Outillage / Peinture | D31: Unité | F31: 750 | G31: 1000 | H31: 0.33333333 | L31: 0 | M31: 0 | N31: 0 | O31: 8 | P31: RÉAPPROVISIONNER | Q31: 0
A32: EMTOP | B32: Maillet en caoutchouc blanc 8OZ/220G/marteau pour carreaux | C32: Gros œuvre | D32: Unité | F32: 1600 | G32: 2500 | H32: 0.5625 | I32: 3 | J32: 2000 | L32: 0 | M32: 0 | N32: 3 | O32: 8 | P32: RÉAPPROVISIONNER | Q32: 4800
A33: HERO | B33: Baguette Chinoise 2.5/CT | C33: Gros œuvre | D33: Unité | F33: 1688 | G33: 2500 | H33: 0.48104265 | I33: 8 | J33: 2200 | L33: 0 | M33: 0 | N33: 8 | O33: 8 | P33: RÉAPPROVISIONNER | Q33: 13504
A34: HERO | B34: Baguette Chinoise 3.15/CT | C34: Gros œuvre | D34: Unité | F34: 3750 | G34: 5000 | H34: 0.33333333 | J34: 4500 | L34: 0 | M34: 0 | N34: 0 | O34: 8 | P34: RÉAPPROVISIONNER | Q34: 0
A35: FORCE | B35: ROBINET PUISAGE A BOISSEAU 16/20 | C35: Plomberie | D35: Unité | F35: 1750 | G35: 2500 | H35: 0.42857143 | J35: 2000 | L35: 0 | M35: 0 | N35: 0 | O35: 8 | P35: RÉAPPROVISIONNER | Q35: 0
A36: MAROC | B36: Gamette | C36: Gros œuvre | D36: Unité | F36: 1800 | G36: 3000 | H36: 0.66666667 | I36: 15 | J36: 2500 | L36: 0 | M36: 0 | N36: 15 | O36: 8 | P36: OK | Q36: 27000
A37: INDUSTRAP | B37: PORTE PAPIER PLASTIQUE | C37: Plomberie | D37: Unité | F37: 1000 | G37: 2500 | H37: 1.5 | I37: 20 | J37: 2000 | L37: 0 | M37: 0 | N37: 20 | O37: 8 | P37: OK | Q37: 20000
A38: INDUSTRAP | B38: PORTE SAVON PLASTIQUE | C38: Plomberie | D38: Unité | F38: 600 | G38: 2000 | H38: 2.3333333 | I38: 20 | J38: 1500 | L38: 0 | M38: 0 | N38: 20 | O38: 8 | P38: OK | Q38: 12000
A39: INDUSTRAP | B39: TABLETTE EN PLASTIQUE | C39: Plomberie | D39: Unité | F39: 1200 | G39: 3000 | H39: 1.5 | I39: 10 | J39: 2000 | L39: 0 | M39: 0 | N39: 10 | O39: 8 | P39: OK | Q39: 12000
A40: INDUSTRAP | B40: PORTE SERVIETTE EN PLASTIQUE | C40: Plomberie | D40: Unité | F40: 1000 | G40: 3000 | H40: 2 | I40: 10 | J40: 2000 | L40: 0 | M40: 0 | N40: 10 | O40: 8 | P40: OK | Q40: 10000
A41: FORCE | B41: PORTE SERVIETTECHROME 2 BRANCHES | C41: Plomberie | D41: Unité | F41: 2000 | G41: 5000 | H41: 1.5 | I41: 5 | J41: 3500 | L41: 0 | M41: 0 | N41: 5 | O41: 8 | P41: RÉAPPROVISIONNER | Q41: 10000
...

Sheet Mouvements
A2: JOURNAL DES MOUVEMENTS (ENTRÉES / SORTIES)
A3: Saisie quotidienne de toutes les ventes en caisse et des réapprovisionnements
A4: Date | B4: Type Mouvement | C4: Code Article | D4: Catégorie | E4: Quantité | F4: Prix Unitaire (FCFA) | G4: Total FCFA | H4: Client / Fournisseur
A5: 2026-08-20 | B5: Entrée | C5: ART-001 | E5: 50 | F5: 4200 | G5: 210000 | H5: SOCIMAT Fournisseur
A6: 2026-08-20 | B6: Entrée | C6: ART-002 | E6: 100 | F6: 3100 | G6: 310000 | H6: SOTACI Ferraille
A7: 2026-08-21 | B7: Sortie | C7: ART-001 | E7: 10 | F7: 4800 | G7: 48000 | H7: Entreprise BTP PHOENIX
A8: 2026-08-21 | B8: Sortie | C8: ART-002 | E8: 15 | F8: 3700 | G8: 55500 | H8: Client Comptoir - M. Traoré
A9: 2026-08-21 | B9: Sortie | C9: ART-003 | E9: 5 | F9: 3200 | G9: 16000 | H9: Plombier Kouassi
A10: 2026-08-22 | B10: Sortie | C10: ART-005 | E10: 4 | F10: 17500 | G10: 70000 | H10: Electricien Koffi
A11: 2026-08-22 | B11: Entrée | C11: ART-004 | E11: 10 | F11: 18500 | G11: 185000 | H11: Peintures SIPEC
A12: 2026-08-22 | B12: Sortie | C12: ART-004 | E12: 2 | F12: 23500 | G12: 47000 | H12: Client Particulier
A13: 2026-08-22 | B13: Sortie | C13: ART-006 | E13: 500 | F13: 320 | G13: 160000 | H13: Chantier Résidence Angré
A14: 2026-08-22 | B14: Sortie | C14: ART-001 | E14: 45 | F14: 4800 | G14: 216000 | H14: Client BTP - Extension Villa
D15: TOTAL DES FLUX | E15: 741 | G15: 1317500
A16: 2026-09-28 | B16: Sortie | C16: ART-PIN | D16: PINCEAU N°70 | E16: 1 | F16: 500 | G16: 500 | H16: Client Comptoir
A17: 2026-09-28 | B17: Sortie | C17: ART-PIN | D17: PINCEAU N°50 | E17: 1 | F17: 500 | G17: 500 | H17: Client Comptoir
A18: 2026-09-28 | B18: Sortie | C18: ART-CHE | D18: CHEVILLE + VIS N°12 25PCS/BTE | E18: 1 | F18: 1000 | G18: 1000 | H18: Client Comptoir
A19: 46293 | B19: Sortie | C19: ART | D19: equerre | E19: 1 | F19: 1000 | G19: 1000 | H19: Client Comptoir
A20: 46293 | B20: Sortie | C20: ART | D20: platre | E20: 1 | F20: 500 | G20: 500 | H20: Client Comptoir
A21: 46293 | B21: Sortie | C21: ART | D21: Tourne vis | E21: 1 | F21: 1000 | G21: 1000 | H21: Client Comptoir
A22: 46293 | B22: Sortie | C22: ART | D22: Petit pinceau(dessin) | E22: 2 | F22: 300 | G22: 300 | H22: Client Comptoir
